Workbook

Sheet Sheet4
A1: Month-wise Sales Trend (Pivot Table → Group by Month)
A3: Days (Date) | B3: Sum of Sales | C3: Sum of Sales2 | D3: Sum of Profit% | E3: Sum of Profit%2
A4: 01-Jan | B4: 250000 | D4: 0.15
A5: 02-Jan | B5: 200000 | C5: -50000 | D5: 0.15 | E5: 0
A6: 03-Jan | B6: 30000 | C6: -170000 | D6: 0.2 | E6: 0.05
A7: 04-Jan | B7: 60000 | C7: 30000 | D7: 0.25 | E7: 0.05
A8: 05-Jan | B8: 120000 | C8: 60000 | D8: 0.15 | E8: -0.1
A9: 06-Jan | B9: 20000 | C9: -100000 | D9: 0.2 | E9: 0.05
A10: 07-Jan | B10: 30000 | C10: 10000 | D10: 0.25 | E10: 0.05
A11: 08-Jan | B11: 36000 | C11: 6000 | D11: 0.15 | E11: -0.1
A12: 09-Jan | B12: 35000 | C12: -1000 | D12: 0.2 | E12: 0.05
A13: 10-Jan | B13: 120000 | C13: 85000 | D13: 0.25 | E13: 0.05
A14: 11-Jan | B14: 100000 | C14: -20000 | D14: 0.15 | E14: -0.1
A15: 12-Jan | B15: 30000 | C15: -70000 | D15: 0.2 | E15: 0.05
A16: 13-Jan | B16: 50000 | C16: 20000 | D16: 0.25 | E16: 0.05
... A53: 19-Feb | B53: 450000 | C53: 410000 | D53: 0.15 | E53: -0.05
A54: Grand Total | B54: 3315200 | D54: 9.85

Sheet Sheet9
A3: Months (Date) | B3: Days (Date) | C3: Sum of Sales | D3: Sum of Profit | E3: Sum of Profit%
A4: Jan | B4: 01-Jan | C4: 250000 | D4: 37500 | E4: 0.15
B5: 02-Jan | C5: 200000 | D5: 30000 | E5: 0.15
B6: 03-Jan | C6: 30000 | D6: 6000 | E6: 0.2
B7: 04-Jan | C7: 60000 | D7: 15000 | E7: 0.25
B8: 05-Jan | C8: 120000 | D8: 18000 | E8: 0.15
B9: 06-Jan | C9: 20000 | D9: 4000 | E9: 0.2
B10: 07-Jan | C10: 30000 | D10: 7500 | E10: 0.25
B11: 08-Jan | C11: 36000 | D11: 5400 | E11: 0.15
B12: 09-Jan | C12: 35000 | D12: 7000 | E12: 0.2
B13: 10-Jan | C13: 120000 | D13: 30000 | E13: 0.25
B14: 11-Jan | C14: 100000 | D14: 15000 | E14: 0.15
B15: 12-Jan | C15: 30000 | D15: 6000 | E15: 0.2
B16: 13-Jan | C16: 50000 | D16: 12500 | E16: 0.25
... B34: 31-Jan | C34: 45000 | D34: 11250 | E34: 0.25
A35: Jan Total | C35: 1795200 | D35: 335890 | E35: 6.15
A36: Feb | B36: 01-Feb | C36: 25000 | D36: 3750 | E36: 0.15
B37: 02-Feb | C37: 16000 | D37: 3200 | E37: 0.2
B38: 03-Feb | C38: 60000 | D38: 15000 | E38: 0.25
B39: 04-Feb | C39: 66000 | D39: 9900 | E39: 0.15
B40: 05-Feb | C40: 15000 | D40: 3000 | E40: 0.2
B41: 06-Feb | C41: 24000 | D41: 6000 | E41: 0.25
B42: 07-Feb | C42: 60000 | D42: 9000 | E42: 0.15
B43: 08-Feb | C43: 16000 | D43: 3200 | E43: 0.2
B44: 09-Feb | C44: 40000 | D44: 10000 | E44: 0.25
B45: 10-Feb | C45: 25000 | D45: 3750 | E45: 0.15
B46: 11-Feb | C46: 18000 | D46: 3600 | E46: 0.2
B47: 12-Feb | C47: 56000 | D47: 14000 | E47: 0.25
B48: 13-Feb | C48: 70000 | D48: 10500 | E48: 0.15
... B54: 19-Feb | C54: 450000 | D54: 67500 | E54: 0.15
A55: Feb Total | C55: 1520000 | D55: 262700 | E55: 3.7

Sheet Sheet10
A3: Month | B3: Total Sales | C3: Total Profit
A4: Jan | B4: 1795200 | C4: 335890
A5: Feb | B5: 1520000 | C5: 262700
A6: Grand Total | B6: 3315200 | C6: 598590

Sheet Sheet1
A1: Date | B1: Region | C1: Product | D1: Category | E1: Quantity | F1: Unit Price | G1: Sales | H1: Profit | I1: Profit% | K1: Region-wise Sales → | P1: category wise Sales | U1: Region wise category sales
A2: 45658 | B2: North | C2: =TRIM("Laptop") -> Laptop | D2: Electronics | E2: 5 | F2: 50000 | G2: =E2*F2 -> 250000 | H2: =G2*15/100 -> 37500 | I2: =H2/G2 -> 0.15 | K2: Region | L2: sales | M2: Profit | N2: Profit% | P2: category | Q2: sales | R2: Profit | S2: profit% | V2: Electronics | W2: Fashion | X2: Furniture | Z2: Salaes of north region
A3: 45659 | B3: South | C3: Mobile | D3: Electronics | E3: 10 | F3: 20000 | G3: =E3*F3 -> 200000 | H3: =G3*15/100 -> 30000 | I3: =H3/G3 -> 0.15 | J3: =TRIM(C3) -> Mobile | K3: North | L3: =SUMIF(B2:B51,K3,G2:G51) -> 701000 | M3: =SUMIF(B2:B51,K3,H2:H51) -> 123750 | N3: =M3/L3*100 -> 17.653352 | P3: Electronics | Q3: =SUMIF(D2:D51,P3,G2:G51) -> 2106000 | R3: =SUMIF(D2:D51,P3,H2:H51) -> 315900 | S3: =SUMIF($D$2:$D$51,P3,$I$2:$I$51) -> 2.7 | U3: North | V3: =SUMIFS($G$2:$G$51,$B$2:$B$51,$U3,$D$2:$D$51,V$2) -> 451000 | W3: =SUMIFS($G$2:$G$51,$B$2:$B$51,$U3,$D$2:$D$51,W$2) -> 128000 | X3: =SUMIFS($G$2:$G$51,$B$2:$B$51,$U3,$D$2:$D$51,X$2) -> 122000 | Z3: {=_xlfn._xlws.FILTER(A1:I52,B1:B52="North")} -> 45658 | AA3: North | AB3: Laptop | AC3: Electronics | AD3: 5 | AE3: 50000 | AF3: 250000 | AG3: 37500 | AH3: 0.15
A4: 45660 | B4: East | C4: Shoes | D4: Fashion | E4: 15 | F4: 2000 | G4: =E4*F4 -> 30000 | H4: 6000 | I4: =H4/G4 -> 0.2 | J4: =TRIM(C4) -> Shoes | K4: South | L4: =SUMIF(B3:B52,K4,G3:G52) -> 1486200 | M4: =SUMIF(B3:B52,K4,H3:H52) -> 260540 | N4: =M4/L4*100 -> 17.530615 | P4: Fashion | Q4: =SUMIF(D3:D52,P4,G3:G52) -> 392200 | R4: =SUMIF(D3:D52,P4,H3:H52) -> 78440 | S4: =SUMIF($D$2:$D$51,P4,$I$2:$I$51) -> 3.4 | U4: South | V4: =SUMIFS($G$2:$G$51,$B$2:$B$51,$U4,$D$2:$D$51,V$2) -> 874000 | W4: =SUMIFS($G$2:$G$51,$B$2:$B$51,$U4,$D$2:$D$51,W$2) -> 72200 | X4: =SUMIFS($G$2:$G$51,$B$2:$B$51,$U4,$D$2:$D$51,X$2) -> 340000 | Z4: 45662 | AA4: North | AB4: Tablet | AC4: Electronics | AD4: 8 | AE4: 15000 | AF4: 120000 | AG4: 18000 | AH4: 0.15
A5: 45661 | B5: West | C5: Sofa | D5: Furniture | E5: 2 | F5: 30000 | G5: =E5*F5 -> 60000 | H5: 15000 | I5: =H5/G5 -> 0.25 | J5: =TRIM(C5) -> Sofa | K5: East | L5: =SUMIF(B4:B53,K5,G4:G53) -> 860000 | M5: =SUMIF(B4:B53,K5,H4:H53) -> 148750 | N5: =M5/L5*100 -> 17.296512 | P5: Furniture | Q5: =SUMIF(D4:D53,P5,G4:G53) -> 817000 | R5: =SUMIF(D4:D53,P5,H4:H53) -> 204250 | S5: =SUMIF($D$2:$D$51,P5,$I$2:$I$51) -> 3.75 | U5: East | V5: =SUMIFS($G$2:$G$51,$B$2:$B$51,$U5,$D$2:$D$51,V$2) -> 620000 | W5: =SUMIFS($G$2:$G$51,$B$2:$B$51,$U5,$D$2:$D$51,W$2) -> 85000 | X5: =SUMIFS($G$2:$G$51,$B$2:$B$51,$U5,$D$2:$D$51,X$2) -> 155000 | Z5: 45666 | AA5: North | AB5: Jacket | AC5: Fashion | AD5: 10 | AE5: 3500 | AF5: 35000 | AG5: 7000 | AH5: 0.2
A6: 45662 | B6: North | C6: Tablet | D6: Electronics | E6: 8 | F6: 15000 | G6: =E6*F6 -> 120000 | H6: 18000 | I6: =H6/G6 -> 0.15 | J6: =TRIM(C6) -> Tablet | K6: West | L6: =SUMIF(B5:B54,K6,G5:G54) -> 468000 | M6: =SUMIF(B5:B54,K6,H5:H54) -> 95550 | N6: =M6/L6*100 -> 20.416667 | U6: West | V6: =SUMIFS($G$2:$G$51,$B$2:$B$51,$U6,$D$2:$D$51,V$2) -> 161000 | W6: =SUMIFS($G$2:$G$51,$B$2:$B$51,$U6,$D$2:$D$51,W$2) -> 107000 | X6: =SUMIFS($G$2:$G$51,$B$2:$B$51,$U6,$D$2:$D$51,X$2) -> 200000 | Z6: 45670 | AA6: North | AB6: Table | AC6: Furniture | AD6: 5 | AE6: 10000 | AF6: 50000 | AG6: 12500 | AH6: 0.25
A7: 45663 | B7: South | C7: Shirt | D7: Fashion | E7: 20 | F7: 1000 | G7: =E7*F7 -> 20000 | H7: 4000 | I7: =H7/G7 -> 0.2 | J7: =TRIM(C7) -> Shirt | Z7: 45674 | AA7: North | AB7: Speaker | AC7: Electronics | AD7: 9 | AE7: 4000 | AF7: 36000 | AG7: 5400 | AH7: 0.15
A8: 45664 | B8: East | C8: Chair | D8: Furniture | E8: 6 | F8: 5000 | G8: =E8*F8 -> 30000 | H8: 7500 | I8: =H8/G8 -> 0.25 | J8: =TRIM(C8) -> Chair | K8: =AVERAGE(I2:I51) -> 0.197 | Z8: 45678 | AA8: North | AB8: Watch | AC8: Fashion | AD8: 6 | AE8: 5000 | AF8: 30000 | AG8: 6000 | AH8: 0.2
A9: 45665 | B9: West | C9: Headphones | D9: Electronics | E9: 12 | F9: 3000 | G9: =E9*F9 -> 36000 | H9: 5400 | I9: =H9/G9 -> 0.15 | J9: =TRIM(C9) -> Headphones | N9: Top 5 Products by Sales | S9: Month | T9: Sum of Sales | U9: Sum of Sales2 | Z9: 45682 | AA9: North | AB9: Desk | AC9: Furniture | AD9: 4 | AE9: 12000 | AF9: 48000 | AG9: 12000 | AH9: 0.25
A10: 45666 | B10: North | C10: Jacket | D10: Fashion | E10: 10 | F10: 3500 | G10: =E10*F10 -> 35000 | H10: 7000 | I10: =H10/G10 -> 0.2 | J10: =TRIM(C10) -> Jacket | K10: Product | L10: sales | O10: Sales | P10: Product | S10: 45662 | T10: 2429000 | Z10: 45686 | AA10: North | AB10: Mouse | AC10: Electronics | AD10: 20 | AE10: 1000 | AF10: 20000 | AG10: 3000 | AH10: 0.15
A11: 45667 | B11: South | C11: Bed | D11: Furniture | E11: 3 | F11: 40000 | G11: =E11*F11 -> 120000 | H11: 30000 | I11: =H11/G11 -> 0.25 | J11: =TRIM(C11) -> Bed | K11: Laptop | L11: =SUMIFS($G$2:$G$51,$C$2:$C$51,$K11) -> 700000 | M11: 80000 | N11: 1 | O11: =LARGE($L$11:$L$22,N11) -> 700000 | P11: =INDEX($K$11:$K$22,MATCH($O11,$L$11:$L$22,0)) -> Laptop | S11: Feb | T11: 1864500 | U11: -564500 | Z11: 45690 | AA11: North | AB11: Kurta | AC11: Fashion | AD11: 8 | AE11: 2000 | AF11: 16000 | AG11: 3200 | AH11: 0.2
A12: 45668 | B12: East | C12: Camera | D12: Electronics | E12: 4 | F12: 25000 | G12: =E12*F12 -> 100000 | H12: 15000 | I12: =H12/G12 -> 0.15 | J12: =TRIM(C12) -> Camera | K12: Mobile | L12: =SUMIFS($G$2:$G$51,$C$2:$C$51,$K12) -> 600000 | M12: 40000 | N12: 2 | O12: =LARGE($L$11:$L$22,N12) -> 600000 | P12: =INDEX($K$11:$K$22,MATCH($O12,$L$11:$L$22,0)) -> Mobile | Z12: 45694 | AA12: North | AB12: Lamp | AC12: Furniture | AD12: 6 | AE12: 4000 | AF12: 24000 | AG12: 6000 | AH12: 0.25
A13: 45669 | B13: West | C13: Dress | D13: Fashion | E13: 12 | F13: 2500 | G13: =E13*F13 -> 30000 | H13: 6000 | I13: =H13/G13 -> 0.2 | J13: =TRIM(C13) -> Dress | K13: Shoes | L13: =SUMIFS($G$2:$G$51,$C$2:$C$51,$K13) -> 70000 | M13: 2000 | N13: 3 | O13: =LARGE($L$11:$L$22,N13) -> 210000 | P13: =INDEX($K$11:$K$22,MATCH($O13,$L$11:$L$22,0)) -> Bed | T13: =SUMIF(A1:I51,S10,G2:G51) -> 20000 | Z13: 45698 | AA13: North | AB13: Earbuds | AC13: Electronics | AD13: 10 | AE13: 2500 | AF13: 25000 | AG13: 3750 | AH13: 0.15
A14: 45670 | B14: North | C14: Table | D14: Furniture | E14: 5 | F14: 10000 | G14: =E14*F14 -> 50000 | H14: 12500 | I14: =H14/G14 -> 0.25 | J14: =TRIM(C14) -> Table | K14: Sofa | L14: =SUMIFS($G$2:$G$51,$C$2:$C$51,$K14) -> 60000 | M14: 45000 | N14: 4 | O14: =LARGE($L$11:$L$22,N14) -> 120000 | P14: =INDEX($K$11:$K$22,MATCH($O14,$L$11:$L$22,0)) -> Tablet | Z14: 45702 | AA14: North | AB14: Tie | AC14: Fashion | AD14: 10 | AE14: 700 | AF14: 7000 | AG14: 1400 | AH14: 0.2
A15: 45671 | B15: South | C15: Monitor | D15: Electronics | E15: 7 | F15: 12000 | G15: =E15*F15 -> 84000 | H15: 12600 | I15: =H15/G15 -> 0.15 | J15: =TRIM(C15) -> Monitor | K15: Tablet | L15: =SUMIFS($G$2:$G$51,$C$2:$C$51,$K15) -> 120000 | M15: 25000 | N15: 5 | O15: =LARGE($L$11:$L$22,N15) -> 80000 | P15: =INDEX($K$11:$K$22,MATCH($O15,$L$11:$L$22,0)) -> TV | Q15: =LEN(C3) -> 6 | Z15: 45706 | AA15: North | AB15: Shoes | AC15: Fashion | AD15: 20 | AE15: 2000 | AF15: 40000 | AG15: 8000 | AH15: 0.2
A16: 45672 | B16: East | C16: Jeans | D16: Fashion | E16: 18 | F16: 1500 | G16: =E16*F16 -> 27000 | H16: 5400 | I16: =H16/G16 -> 0.2 | J16: =TRIM(C16) -> Jeans | K16: Shirt | L16: =SUMIFS($G$2:$G$51,$C$2:$C$51,$K16) -> 20000 | M16: 1000 | Q16: =LEN(C4) -> 5
A17: 45673 | B17: West | C17: Cupboard | D17: Furniture | E17: 2 | F17: 25000 | G17: =E17*F17 -> 50000 | H17: 12500 | I17: =H17/G17 -> 0.25 | J17: =TRIM(C17) -> Cupboard | K17: Chair | L17: =SUMIFS($G$2:$G$51,$C$2:$C$51,$K17) -> 30000 | M17: 1000 | Q17: =LEN(C5) -> 4
A18: 45674 | B18: North | C18: Speaker | D18: Electronics | E18: 9 | F18: 4000 | G18: =E18*F18 -> 36000 | H18: 5400 | I18: =H18/G18 -> 0.15 | J18: =TRIM(C18) -> Speaker | K18: Headphones | L18: =SUMIFS($G$2:$G$51,$C$2:$C$51,$K18) -> 36000 | M18: 2000 | Q18: =LEN(C6) -> 6
A19: 45675 | B19: South | C19: Skirt | D19: Fashion | E19: 14 | F19: 1800 | G19: =E19*F19 -> 25200 | H19: 5040 | I19: =H19/G19 -> 0.2 | J19: =TRIM(C19) -> Skirt | K19: Jacket | L19: =SUMIFS($G$2:$G$51,$C$2:$C$51,$K19) -> 77000 | M19: 1500 | Q19: =LEN(C7) -> 5
A20: 45676 | B20: East | C20: Stool | D20: Furniture | E20: 8 | F20: 3000 | G20: =E20*F20 -> 24000 | H20: 6000 | I20: =H20/G20 -> 0.25 | J20: =TRIM(C20) -> Stool | K20: Bed | L20: =SUMIFS($G$2:$G$51,$C$2:$C$51,$K20) -> 210000 | M20: 45000 | Q20: =LEN(C8) -> 5
A21: 45677 | B21: West | C21: Keyboard | D21: Electronics | E21: 15 | F21: 2000 | G21: =E21*F21 -> 30000 | H21: 4500 | I21: =H21/G21 -> 0.15 | J21: =TRIM(C21) -> Keyboard | K21: Watch | L21: =SUMIFS($G$2:$G$51,$C$2:$C$51,$K21) -> 30000 | M21: 4000 | Q21: =LEN(C9) -> 10 | R21: =(5*50000)-250000 -> 0
A22: 45678 | B22: North | C22: Watch | D22: Fashion | E22: 6 | F22: 5000 | G22: =E22*F22 -> 30000 | H22: 6000 | I22: =H22/G22 -> 0.2 | J22: =TRIM(C22) -> Watch | K22: TV | L22: =SUMIFS($G$2:$G$51,$C$2:$C$51,$K22) -> 80000 | M22: 50000
A23: 45679 | B23: South | C23: Wardrobe | D23: Furniture | E23: 2 | F23: 35000 | G23: =E23*F23 -> 70000 | H23: 17500 | I23: =H23/G23 -> 0.25 | J23: =TRIM(C23) -> Wardrobe | V23: {=_xlfn._xlws.SORT(_xlfn.ANCHORARRAY(Z3),7,-1)} -> 45658 | W23: North | X23: Laptop | Y23: Electronics | Z23: 5 | AA23: 50000 | AB23: 250000 | AC23: 37500 | AD23: 0.15
A24: 45680 | B24: East | C24: Printer | D24: Electronics | E24: 3 | F24: 18000 | G24: =E24*F24 -> 54000 | H24: 8100 | I24: =H24/G24 -> 0.15 | J24: =TRIM(C24) -> Printer | O24: Top 5 Products by profit | R24: =LARGE(G2:G51,N26) -> 450000 | V24: 45662 | W24: North | X24: Tablet | Y24: Electronics | Z24: 8 | AA24: 15000 | AB24: 120000 | AC24: 18000 | AD24: 0.15
A25: 45681 | B25: West | C25: T-Shirt | D25: Fashion | E25: 25 | F25: 800 | G25: =E25*F25 -> 20000 | H25: 4000 | I25: =H25/G25 -> 0.2 | J25: =TRIM(C25) -> T-Shirt | K25: Product | L25: profit | V25: 45670 | W25: North | X25: Table | Y25: Furniture | Z25: 5 | AA25: 10000 | AB25: 50000 | AC25: 12500 | AD25: 0.25
A26: 45682 | B26: North | C26: Desk | D26: Furniture | E26: 4 | F26: 12000 | G26: =E26*F26 -> 48000 | H26: 12000 | I26: =H26/G26 -> 0.25 | J26: =TRIM(C26) -> Desk | K26: Laptop | L26: =SUMIF($C$2:$C$51,K26,$H$2:$H$51) -> 105000 | N26: 1 | O26: =LARGE(L26:L37,N26) -> 105000 | P26: =INDEX($K$26:$K$37,MATCH(O26,$L$26:$L$37,0)) -> Laptop | V26: 45682 | W26: North | X26: Desk | Y26: Furniture | Z26: 4 | AA26: 12000 | AB26: 48000 | AC26: 12000 | AD26: 0.25
A27: 45683 | B27: South | C27: TV | D27: Electronics | E27: 2 | F27: 40000 | G27: =E27*F27 -> 80000 | H27: 12000 | I27: =H27/G27 -> 0.15 | J27: =TRIM(C27) -> TV | K27: Mobile | L27: =SUMIF($C$2:$C$51,K27,$H$2:$H$51) -> 90000 | N27: 2 | O27: =LARGE(L27:L38,N27) -> 52500 | P27: =INDEX($K$26:$K$37,MATCH(O27,$L$26:$L$37,0)) -> Bed | V27: 45706 | W27: North | X27: Shoes | Y27: Fashion | Z27: 20 | AA27: 2000 | AB27: 40000 | AC27: 8000 | AD27: 0.2
A28: 45684 | B28: East | C28: Belt | D28: Fashion | E28: 10 | F28: 1200 | G28: =E28*F28 -> 12000 | H28: 2400 | I28: =H28/G28 -> 0.2 | J28: =TRIM(C28) -> Belt | K28: Shoes | L28: =SUMIF($C$2:$C$51,K28,$H$2:$H$51) -> 14000 | N28: 3 | O28: =LARGE(L28:L39,N28) -> 15400 | P28: =INDEX($K$26:$K$37,MATCH(O28,$L$26:$L$37,0)) -> Jacket | V28: 45674 | W28: North | X28: Speaker | Y28: Electronics | Z28: 9 | AA28: 4000 | AB28: 36000 | AC28: 5400 | AD28: 0.15
A29: 45685 | B29: West | C29: Recliner | D29: Furniture | E29: 1 | F29: 50000 | G29: =E29*F29 -> 50000 | H29: 12500 | I29: =H29/G29 -> 0.25 | J29: =TRIM(C29) -> Recliner | K29: Sofa | L29: =SUMIF($C$2:$C$51,K29,$H$2:$H$51) -> 15000 | N29: 4 | O29: =LARGE(L29:L40,N29) -> 15000 | P29: =INDEX($K$26:$K$37,MATCH(O29,$L$26:$L$37,0)) -> Sofa | V29: 45666 | W29: North | X29: Jacket | Y29: Fashion | Z29: 10 | AA29: 3500 | AB29: 35000 | AC29: 7000 | AD29: 0.2
A30: 45686 | B30: North | C30: Mouse | D30: Electronics | E30: 20 | F30: 1000 | G30: =E30*F30 -> 20000 | H30: 3000 | I30: =H30/G30 -> 0.15 | J30: =TRIM(C30) -> Mouse | K30: Tablet | L30: =SUMIF($C$2:$C$51,K30,$H$2:$H$51) -> 18000 | N30: 5 | O30: =LARGE(L30:L41,N30) -> 7500 | P30: =INDEX($K$26:$K$37,MATCH(O30,$L$26:$L$37,0)) -> Chair | V30: 45678 | W30: North | X30: Watch | Y30: Fashion | Z30: 6 | AA30: 5000 | AB30: 30000 | AC30: 6000 | AD30: 0.2
A31: 45687 | B31: South | C31: Cap | D31: Fashion | E31: 15 | F31: 600 | G31: =E31*F31 -> 9000 | H31: 1800 | I31: =H31/G31 -> 0.2 | J31: =TRIM(C31) -> Cap | K31: Shirt | L31: =SUMIF($C$2:$C$51,K31,$H$2:$H$51) -> 4000 | V31: 45698 | W31: North | X31: Earbuds | Y31: Electronics | Z31: 10 | AA31: 2500 | AB31: 25000 | AC31: 3750 | AD31: 0.15
A32: 45688 | B32: East | C32: Shelf | D32: Furniture | E32: 3 | F32: 15000 | G32: =E32*F32 -> 45000 | H32: 11250 | I32: =H32/G32 -> 0.25 | J32: =TRIM(C32) -> Shelf | K32: Chair | L32: =SUMIF($C$2:$C$51,K32,$H$2:$H$51) -> 7500 | V32: 45694 | W32: North | X32: Lamp | Y32: Furniture | Z32: 6 | AA32: 4000 | AB32: 24000 | AC32: 6000 | AD32: 0.25
A33: 45689 | B33: West | C33: Router | D33: Electronics | E33: 5 | F33: 5000 | G33: =E33*F33 -> 25000 | H33: 3750 | I33: =H33/G33 -> 0.15 | J33: =TRIM(C33) -> Router | K33: Headphones | L33: =SUMIF($C$2:$C$51,K33,$H$2:$H$51) -> 5400 | N33: 45689 | O33: West | P33: Bed | Q33: Furniture | R33: 4 | S33: 40000 | T33: 160000 | V33: 45686 | W33: North | X33: Mouse | Y33: Electronics | Z33: 20 | AA33: 1000 | AB33: 20000 | AC33: 3000 | AD33: 0.15
A34: 45690 | B34: North | C34: Kurta | D34: Fashion | E34: 8 | F34: 2000 | G34: =E34*F34 -> 16000 | H34: 3200 | I34: =H34/G34 -> 0.2 | J34: =TRIM(C34) -> Kurta | K34: Jacket | L34: =SUMIF($C$2:$C$51,K34,$H$2:$H$51) -> 15400 | N34: 45690 | O34: North | P34: Mobile | Q34: Electronics | R34: 7 | S34: 20000 | T34: 140000 | V34: 45690 | W34: North | X34: Kurta | Y34: Fashion | Z34: 8 | AA34: 2000 | AB34: 16000 | AC34: 3200 | AD34: 0.2
A35: 45691 | B35: South | C35: Dining Set | D35: Furniture | E35: 1 | F35: 60000 | G35: =E35*F35 -> 60000 | H35: 15000 | I35: =H35/G35 -> 0.25 | J35: =TRIM(C35) -> Dining Set | K35: Bed | L35: =SUMIF($C$2:$C$51,K35,$H$2:$H$51) -> 52500 | N35: 45691 | O35: South | P35: Shoes | Q35: Fashion | R35: 12 | S35: 2000 | T35: 24000 | V35: 45702 | W35: North | X35: Tie | Y35: Fashion | Z35: 10 | AA35: 700 | AB35: 7000 | AC35: 1400 | AD35: 0.2
A36: 45692 | B36: East | C36: Console | D36: Electronics | E36: 3 | F36: 22000 | G36: =E36*F36 -> 66000 | H36: 9900 | I36: =H36/G36 -> 0.15 | J36: =TRIM(C36) -> Console | K36: Watch | L36: =SUMIF($C$2:$C$51,K36,$H$2:$H$51) -> 6000 | N36: 45692 | O36: East | P36: Sofa | Q36: Furniture | R36: 2 | S36: 30000 | T36: 60000
A37: 45693 | B37: West | C37: Saree | D37: Fashion | E37: 5 | F37: 3000 | G37: =E37*F37 -> 15000 | H37: 3000 | I37: =H37/G37 -> 0.2 | J37: =TRIM(C37) -> Saree | K37: TV | L37: =SUMIF($C$2:$C$51,K37,$H$2:$H$51) -> 12000 | N37: 45693 | O37: West | P37: Laptop | Q37: Electronics | R37: 6 | S37: 50000 | T37: 300000 | V37: {=_xlfn.SEQUENCE(5,7)} -> 1 | W37: 2 | X37: 3 | Y37: 4 | Z37: 5 | AA37: 6 | AB37: 7
A38: 45694 | B38: North | C38: Lamp | D38: Furniture | E38: 6 | F38: 4000 | G38: =E38*F38 -> 24000 | H38: 6000 | I38: =H38/G38 -> 0.25 | J38: =TRIM(C38) -> Lamp | N38: 45694 | O38: North | P38: Jacket | Q38: Fashion | R38: 15 | S38: 3500 | T38: 52500 | V38: 8 | W38: 9 | X38: 10 | Y38: 11 | Z38: 12 | AA38: 13 | AB38: 14
A39: 45695 | B39: South | C39: Drone | D39: Electronics | E39: 2 | F39: 30000 | G39: =E39*F39 -> 60000 | H39: 9000 | I39: =H39/G39 -> 0.15 | J39: =TRIM(C39) -> Drone | K39: Products of Lowest Profit Margin | N39: 45695 | O39: South | P39: Chair | Q39: Furniture | R39: 8 | S39: 5000 | T39: 40000 | V39: 15 | W39: 16 | X39: 17 | Y39: 18 | Z39: 19 | AA39: 20 | AB39: 21
A40: 45696 | B40: East | C40: Blazer | D40: Fashion | E40: 4 | F40: 4000 | G40: =E40*F40 -> 16000 | H40: 3200 | I40: =H40/G40 -> 0.2 | J40: =TRIM(C40) -> Blazer | N40: 45696 | O40: East | P40: Headphones | Q40: Electronics | R40: 20 | S40: 3000 | T40: 60000 | V40: 22 | W40: 23 | X40: 24 | Y40: 25 | Z40: 26 | AA40: 27 | AB40: 28
...

Sheet Sheet7
A2: Region-wise Sales | F2: Category Wise Sales | K2: =Sheet1!U1 -> Region wise category sales | P2: Month wise Total Sales and Total Profit
A3: Region | B3: sales | C3: Profit | D3: Profit% | F3: Category | G3: Sales | H3: Profit | I3: Profit% | K3: Region | L3: =Sheet1!V2 -> Electronics | M3: =Sheet1!W2 -> Fashion | N3: =Sheet1!X2 -> Furniture | P3: Month | Q3: Total Sales | R3: Total Profit
A4: North | B4: 701000 | C4: 123750 | D4: =C4/B4 -> 0.17653352 | F4: Electronics | G4: 2106000 | H4: 315900 | I4: 2.7 | K4: =Sheet1!U3 -> North | L4: =Sheet1!V3 -> 451000 | M4: =Sheet1!W3 -> 128000 | N4: =Sheet1!X3 -> 122000 | P4: Jan | Q4: 1795200 | R4: 335890
A5: South | B5: 1286200 | C5: 230540 | D5: =C5/B5 -> 0.17924118 | F5: Fashion | G5: 392200 | H5: 78440 | I5: 3.4 | K5: =Sheet1!U4 -> South | L5: =Sheet1!V4 -> 874000 | M5: =Sheet1!W4 -> 72200 | N5: =Sheet1!X4 -> 340000 | P5: Feb | Q5: 1520000 | R5: 262700
A6: East | B6: 860000 | C6: 148750 | D6: =C6/B6 -> 0.17296512 | F6: Furniture | G6: 817000 | H6: 204250 | I6: 3.75 | K6: =Sheet1!U5 -> East | L6: =Sheet1!V5 -> 620000 | M6: =Sheet1!W5 -> 85000 | N6: =Sheet1!X5 -> 155000 | P6: Grand Total | Q6: 3315200 | R6: 598590
A7: West | B7: 468000 | C7: 95550 | D7: =C7/B7 -> 0.20416667 | K7: =Sheet1!U6 -> West | L7: =Sheet1!V6 -> 161000 | M7: =Sheet1!W6 -> 107000 | N7: =Sheet1!X6 -> 200000
A24: =Sheet9!A3 -> Months (Date) | B24: =Sheet9!B3 -> Days (Date) | C24: =Sheet9!C3 -> Sum of Sales | D24: =Sheet9!D3 -> Sum of Profit | E24: =Sheet9!E3 -> Sum of Profit% | G24: =Sheet1!O24 -> Top 5 Products by profit | K24: =Sheet1!N9 -> Top 5 Products by Sales
A25: =Sheet9!A4 -> Jan | B25: =Sheet9!B4 -> 01-Jan | C25: =Sheet9!C4 -> 250000 | D25: =Sheet9!D4 -> 37500 | E25: =Sheet9!E4 -> 0.15 | G25: Rank | H25: Profit | I25: Product | K25: Rank | L25: =Sheet1!O10 -> Sales | M25: =Sheet1!P10 -> Product
B26: =Sheet9!B5 -> 02-Jan | C26: =Sheet9!C5 -> 200000 | D26: =Sheet9!D5 -> 30000 | E26: =Sheet9!E5 -> 0.15 | G26: =Sheet1!N26 -> 1 | H26: =Sheet1!O26 -> 105000 | I26: =Sheet1!P26 -> Laptop | K26: =Sheet1!N11 -> 1 | L26: =Sheet1!O11 -> 700000 | M26: =Sheet1!P11 -> Laptop
B27: =Sheet9!B6 -> 03-Jan | C27: =Sheet9!C6 -> 30000 | D27: =Sheet9!D6 -> 6000 | E27: =Sheet9!E6 -> 0.2 | G27: =Sheet1!N27 -> 2 | H27: =Sheet1!O27 -> 52500 | I27: =Sheet1!P27 -> Bed | K27: =Sheet1!N12 -> 2 | L27: =Sheet1!O12 -> 600000 | M27: =Sheet1!P12 -> Mobile
B28: =Sheet9!B7 -> 04-Jan | C28: =Sheet9!C7 -> 60000 | D28: =Sheet9!D7 -> 15000 | E28: =Sheet9!E7 -> 0.25 | G28: =Sheet1!N28 -> 3 | H28: =Sheet1!O28 -> 15400 | I28: =Sheet1!P28 -> Jacket | K28: =Sheet1!N13 -> 3 | L28: =Sheet1!O13 -> 210000 | M28: =Sheet1!P13 -> Bed
B29: =Sheet9!B8 -> 05-Jan | C29: =Sheet9!C8 -> 120000 | D29: =Sheet9!D8 -> 18000 | E29: =Sheet9!E8 -> 0.15 | G29: =Sheet1!N29 -> 4 | H29: =Sheet1!O29 -> 15000 | I29: =Sheet1!P29 -> Sofa | K29: =Sheet1!N14 -> 4 | L29: =Sheet1!O14 -> 120000 | M29: =Sheet1!P14 -> Tablet
B30: =Sheet9!B9 -> 06-Jan | C30: =Sheet9!C9 -> 20000 | D30: =Sheet9!D9 -> 4000 | E30: =Sheet9!E9 -> 0.2 | G30: =Sheet1!N30 -> 5 | H30: =Sheet1!O30 -> 7500 | I30: =Sheet1!P30 -> Chair | K30: =Sheet1!N15 -> 5 | L30: =Sheet1!O15 -> 80000 | M30: =Sheet1!P15 -> TV
B31: =Sheet9!B10 -> 07-Jan | C31: =Sheet9!C10 -> 30000 | D31: =Sheet9!D10 -> 7500 | E31: =Sheet9!E10 -> 0.25
B32: =Sheet9!B11 -> 08-Jan | C32: =Sheet9!C11 -> 36000 | D32: =Sheet9!D11 -> 5400 | E32: =Sheet9!E11 -> 0.15
B33: =Sheet9!B12 -> 09-Jan | C33: =Sheet9!C12 -> 35000 | D33: =Sheet9!D12 -> 7000 | E33: =Sheet9!E12 -> 0.2
B34: =Sheet9!B13 -> 10-Jan | C34: =Sheet9!C13 -> 120000 | D34: =Sheet9!D13 -> 30000 | E34: =Sheet9!E13 -> 0.25
B35: =Sheet9!B14 -> 11-Jan | C35: =Sheet9!C14 -> 100000 | D35: =Sheet9!D14 -> 15000 | E35: =Sheet9!E14 -> 0.15
B36: =Sheet9!B15 -> 12-Jan | C36: =Sheet9!C15 -> 30000 | D36: =Sheet9!D15 -> 6000 | E36: =Sheet9!E15 -> 0.2
B37: =Sheet9!B16 -> 13-Jan | C37: =Sheet9!C16 -> 50000 | D37: =Sheet9!D16 -> 12500 | E37: =Sheet9!E16 -> 0.25
B38: =Sheet9!B17 -> 14-Jan | C38: =Sheet9!C17 -> 84000 | D38: =Sheet9!D17 -> 12600 | E38: =Sheet9!E17 -> 0.15
B39: =Sheet9!B18 -> 15-Jan | C39: =Sheet9!C18 -> 27000 | D39: =Sheet9!D18 -> 5400 | E39: =Sheet9!E18 -> 0.2
B40: =Sheet9!B19 -> 16-Jan | C40: =Sheet9!C19 -> 50000 | D40: =Sheet9!D19 -> 12500 | E40: =Sheet9!E19 -> 0.25
B41: =Sheet9!B20 -> 17-Jan | C41: =Sheet9!C20 -> 36000 | D41: =Sheet9!D20 -> 5400 | E41: =Sheet9!E20 -> 0.15
B42: =Sheet9!B21 -> 18-Jan | C42: =Sheet9!C21 -> 25200 | D42: =Sheet9!D21 -> 5040 | E42: =Sheet9!E21 -> 0.2
... B55: =Sheet9!B34 -> 31-Jan | C55: =Sheet9!C34 -> 45000 | D55: =Sheet9!D34 -> 11250 | E55: =Sheet9!E34 -> 0.25
A56: =Sheet9!A35 -> Jan Total | B56: =Sheet9!B35 -> 0 | C56: =Sheet9!C35 -> 1795200 | D56: =Sheet9!D35 -> 335890 | E56: =Sheet9!E35 -> 6.15
B57: =Sheet9!B36 -> 01-Feb | C57: =Sheet9!C36 -> 25000 | D57: =Sheet9!D36 -> 3750 | E57: =Sheet9!E36 -> 0.15
B58: =Sheet9!B37 -> 02-Feb | C58: =Sheet9!C37 -> 16000 | D58: =Sheet9!D37 -> 3200 | E58: =Sheet9!E37 -> 0.2
B59: =Sheet9!B38 -> 03-Feb | C59: =Sheet9!C38 -> 60000 | D59: =Sheet9!D38 -> 15000 | E59: =Sheet9!E38 -> 0.25
B60: =Sheet9!B39 -> 04-Feb | C60: =Sheet9!C39 -> 66000 | D60: =Sheet9!D39 -> 9900 | E60: =Sheet9!E39 -> 0.15
B61: =Sheet9!B40 -> 05-Feb | C61: =Sheet9!C40 -> 15000 | D61: =Sheet9!D40 -> 3000 | E61: =Sheet9!E40 -> 0.2
B62: =Sheet9!B41 -> 06-Feb | C62: =Sheet9!C41 -> 24000 | D62: =Sheet9!D41 -> 6000 | E62: =Sheet9!E41 -> 0.25
B63: =Sheet9!B42 -> 07-Feb | C63: =Sheet9!C42 -> 60000 | D63: =Sheet9!D42 -> 9000 | E63: =Sheet9!E42 -> 0.15
B64: =Sheet9!B43 -> 08-Feb | C64: =Sheet9!C43 -> 16000 | D64: =Sheet9!D43 -> 3200 | E64: =Sheet9!E43 -> 0.2
B65: =Sheet9!B44 -> 09-Feb | C65: =Sheet9!C44 -> 40000 | D65: =Sheet9!D44 -> 10000 | E65: =Sheet9!E44 -> 0.25
B66: =Sheet9!B45 -> 10-Feb | C66: =Sheet9!C45 -> 25000 | D66: =Sheet9!D45 -> 3750 | E66: =Sheet9!E45 -> 0.15
B67: =Sheet9!B46 -> 11-Feb | C67: =Sheet9!C46 -> 18000 | D67: =Sheet9!D46 -> 3600 | E67: =Sheet9!E46 -> 0.2
B68: =Sheet9!B47 -> 12-Feb | C68: =Sheet9!C47 -> 56000 | D68: =Sheet9!D47 -> 14000 | E68: =Sheet9!E47 -> 0.25
... B74: =Sheet9!B53 -> 18-Feb | C74: =Sheet9!C53 -> 40000 | D74: =Sheet9!D53 -> 8000 | E74: =Sheet9!E53 -> 0.2

Sheet Sheet8

Sheet Sheet2
A1: Region-wise Sales →
B3: Region-wise Sales → SUMIFS
B5: Category-wise Profit → SUMIFS
B7: Top 5 Products → LARGE + INDEX-MATCH
B9: Monthly Trend → Pivot Table (Group by Month)
B11: Conditional Formatting → Profit % < 10% highlight
B13: 3. Dashboard Design
B15: KPIs (Cards):
B19: Total Sales
B21: Total Profit
B23: Average Profit %
B25: Charts:
B29: Region-wise Sales (Bar Chart)
... B186: excel
B188: =SUMIFS($D:$D, $A:$A, "North") -> 0
B190: यहाँ:
B192: $D:$D → वो column है जिसमें Sales values हैं
B194: $A:$A → वो column है जिसमें Region लिखा है
B196: "North" → वो region है जिसका total चाहिए
B198: अगर आप summary table में region का नाम cell में लिखें (जैसे F2 में "North"), तो formula ऐसे होगा:
B200: excel
B202: =SUMIFS($D:$D, $A:$A, F2) -> 0
B204: 👉 इस तरह आप एक ही sheet पर summary बना सकती हैं। अगर चाहें तो हर region का अलग sheet भी बना सकती हैं, लेकिन formula दोनों cases में यही रहेगा।
B206: क्या आप चाहती हैं कि मैं आपके लिए एक ready-made summary table का structure बना दूँ, जिसमें बस आपको अपने column names adjust करने हों?

Sheet Sheet3
A1: Product | K1: Product | O1: Product | P1: price
A2: Laptop | B2: =VLOOKUP(A2,$K$2:$L$25,2,FALSE) -> 80000 | C2: =INDEX($L$2:$L$25,MATCH(A2,$K$2:$K$25,0)) -> 80000 | D2: =INDEX($L$2:$L$25,MATCH(A2,$K$2:$K$25,0)) -> 80000 | E2: =INDEX($L$2:$L$25,MATCH(K2,$K$2:$K$25,0)) -> 80000 | F2: =INDEX($L$2:$L$25,MATCH(A2,$K$2:$K$25,0)) -> 80000 | H2: =INDEX($A$2:$E$25,7,5) -> 7000 | K2: Laptop | L2: 80000 | O2: Laptop | P2: 80000 | R2: =INDEX($K$2:$L$25,MATCH(A2,$K$2:$K$25,0),2) -> 80000
A3: Mobile | B3: =VLOOKUP(A3,$K$2:$L$25,2,FALSE) -> 40000 | C3: =INDEX($L$2:$L$25,MATCH(A3,$K$2:$K$25,0)) -> 40000 | D3: =INDEX($L$2:$L$25,MATCH(A3,$K$2:$K$25,0)) -> 40000 | E3: =INDEX($L$2:$L$25,MATCH(K3,$K$2:$K$25,0)) -> 40000 | K3: Mobile | L3: 40000 | O3: Mobile | P3: 40000 | R3: =INDEX($K$2:$L$25,MATCH(A3,$K$2:$K$25,0),2) -> 40000
A4: Shoes | B4: =VLOOKUP(A4,$K$2:$L$25,2,FALSE) -> 2000 | C4: =INDEX($L$2:$L$25,MATCH(A4,$K$2:$K$25,0)) -> 2000 | D4: =INDEX($L$2:$L$25,MATCH(A4,$K$2:$K$25,0)) -> 2000 | E4: =INDEX($L$2:$L$25,MATCH(K4,$K$2:$K$25,0)) -> 2000 | K4: Shoes | L4: 2000 | O4: Shoes | P4: 2000 | R4: =INDEX($K$2:$L$25,MATCH(A4,$K$2:$K$25,0),2) -> 2000
A5: Sofa | B5: =VLOOKUP(A5,$K$2:$L$25,2,FALSE) -> 45000 | C5: =INDEX($L$2:$L$25,MATCH(A5,$K$2:$K$25,0)) -> 45000 | D5: =INDEX($L$2:$L$25,MATCH(A5,$K$2:$K$25,0)) -> 45000 | E5: =INDEX($L$2:$L$25,MATCH(K5,$K$2:$K$25,0)) -> 45000 | K5: Sofa | L5: 45000 | O5: Sofa | P5: 45000 | R5: =INDEX($K$2:$L$25,MATCH(A5,$K$2:$K$25,0),2) -> 45000
A6: Tablet | B6: =VLOOKUP(A6,$K$2:$L$25,2,FALSE) -> 25000 | C6: =INDEX($L$2:$L$25,MATCH(A6,$K$2:$K$25,0)) -> 25000 | D6: =INDEX($L$2:$L$25,MATCH(A6,$K$2:$K$25,0)) -> 25000 | E6: =INDEX($L$2:$L$25,MATCH(K6,$K$2:$K$25,0)) -> 25000 | K6: Tablet | L6: 25000 | O6: Tablet | P6: 25000 | R6: =INDEX($K$2:$L$25,MATCH(A6,$K$2:$K$25,0),2) -> 25000
A7: Tablet | B7: =VLOOKUP(A7,$K$2:$L$25,2,FALSE) -> 25000 | C7: =INDEX($L$2:$L$25,MATCH(A7,$K$2:$K$25,0)) -> 25000 | D7: =INDEX($L$2:$L$25,MATCH(A7,$K$2:$K$25,0)) -> 25000 | E7: =INDEX($L$2:$L$25,MATCH(K7,$K$2:$K$25,0)) -> 1000 | K7: Shirt | L7: 1000 | O7: Shirt | P7: 1000 | R7: =INDEX($K$2:$L$25,MATCH(A7,$K$2:$K$25,0),2) -> 25000
A8: Chair | B8: =VLOOKUP(A8,$K$2:$L$25,2,FALSE) -> 1000 | C8: =INDEX($L$2:$L$25,MATCH(A8,$K$2:$K$25,0)) -> 1000 | D8: =INDEX($L$2:$L$25,MATCH(A8,$K$2:$K$25,0)) -> 1000 | E8: 7000 | K8: Chair | L8: 1000 | O8: Chair | P8: 1000 | R8: =INDEX($K$2:$L$25,MATCH(A8,$K$2:$K$25,0),2) -> 1000
A9: Headphones | B9: =VLOOKUP(A9,$K$2:$L$25,2,FALSE) -> 2000 | C9: =INDEX($L$2:$L$25,MATCH(A9,$K$2:$K$25,0)) -> 2000 | D9: =INDEX($L$2:$L$25,MATCH(A9,$K$2:$K$25,0)) -> 2000 | E9: =INDEX($L$2:$L$25,MATCH(K9,$K$2:$K$25,0)) -> 2000 | K9: Headphones | L9: 2000 | O9: Headphones | P9: 2000 | R9: =INDEX($K$2:$L$25,MATCH(A9,$K$2:$K$25,0),2) -> 2000
A10: Jacket | B10: =VLOOKUP(A10,$K$2:$L$25,2,FALSE) -> 1500 | C10: =INDEX($L$2:$L$25,MATCH(A10,$K$2:$K$25,0)) -> 1500 | D10: =INDEX($L$2:$L$25,MATCH(A10,$K$2:$K$25,0)) -> 1500 | E10: =INDEX($L$2:$L$25,MATCH(K10,$K$2:$K$25,0)) -> 1500 | K10: Jacket | L10: 1500 | O10: Jacket | P10: 1500 | R10: =INDEX($K$2:$L$25,MATCH(A10,$K$2:$K$25,0),2) -> 1500
A11: Bed | B11: =VLOOKUP(A11,$K$2:$L$25,2,FALSE) -> 45000 | C11: =INDEX($L$2:$L$25,MATCH(A11,$K$2:$K$25,0)) -> 45000 | D11: =INDEX($L$2:$L$25,MATCH(A11,$K$2:$K$25,0)) -> 45000 | E11: =INDEX($L$2:$L$25,MATCH(K11,$K$2:$K$25,0)) -> 45000 | K11: Bed | L11: 45000 | O11: Bed | P11: 45000 | R11: =INDEX($K$2:$L$25,MATCH(A11,$K$2:$K$25,0),2) -> 45000
A12: Camera | B12: =VLOOKUP(A12,$K$2:$L$25,2,FALSE) -> 4000 | C12: =INDEX($L$2:$L$25,MATCH(A12,$K$2:$K$25,0)) -> 4000 | D12: =INDEX($L$2:$L$25,MATCH(A12,$K$2:$K$25,0)) -> 4000 | E12: =INDEX($L$2:$L$25,MATCH(K12,$K$2:$K$25,0)) -> 4000 | K12: Camera | L12: 4000 | O12: Watch | P12: 4000 | R12: =INDEX($K$2:$L$25,MATCH(A12,$K$2:$K$25,0),2) -> 4000
A13: Dress | B13: =VLOOKUP(A13,$K$2:$L$25,2,FALSE) -> 50000 | C13: =INDEX($L$2:$L$25,MATCH(A13,$K$2:$K$25,0)) -> 50000 | D13: =INDEX($L$2:$L$25,MATCH(A13,$K$2:$K$25,0)) -> 50000 | E13: =INDEX($L$2:$L$25,MATCH(K13,$K$2:$K$25,0)) -> 50000 | K13: Dress | L13: 50000 | O13: TV | P13: 50000 | R13: =INDEX($K$2:$L$25,MATCH(A13,$K$2:$K$25,0),2) -> 50000
A14: Table | B14: =VLOOKUP(A14,$K$2:$L$25,2,FALSE) -> 80000 | C14: =INDEX($L$2:$L$25,MATCH(A14,$K$2:$K$25,0)) -> 80000 | D14: =INDEX($L$2:$L$25,MATCH(A14,$K$2:$K$25,0)) -> 80000 | E14: =INDEX($L$2:$L$25,MATCH(K14,$K$2:$K$25,0)) -> 80000 | K14: Table | L14: 80000 | R14: =INDEX($K$2:$L$25,MATCH(A14,$K$2:$K$25,0),2) -> 80000
A15: Monitor | B15: =VLOOKUP(A15,$K$2:$L$25,2,FALSE) -> 40000 | C15: =INDEX($L$2:$L$25,MATCH(A15,$K$2:$K$25,0)) -> 40000 | D15: =INDEX($L$2:$L$25,MATCH(A15,$K$2:$K$25,0)) -> 40000 | E15: =INDEX($L$2:$L$25,MATCH(K15,$K$2:$K$25,0)) -> 40000 | K15: Monitor | L15: 40000 | R15: =INDEX($K$2:$L$25,MATCH(A15,$K$2:$K$25,0),2) -> 40000
A16: Dress | B16: =VLOOKUP(A16,$K$2:$L$25,2,FALSE) -> 50000 | C16: =INDEX($L$2:$L$25,MATCH(A16,$K$2:$K$25,0)) -> 50000 | D16: =INDEX($L$2:$L$25,MATCH(A16,$K$2:$K$25,0)) -> 50000 | E16: =INDEX($L$2:$L$25,MATCH(K16,$K$2:$K$25,0)) -> 2000 | K16: Jeans | L16: 2000 | R16: =INDEX($K$2:$L$25,MATCH(A16,$K$2:$K$25,0),2) -> 50000
A17: Cupboard | B17: =VLOOKUP(A17,$K$2:$L$25,2,FALSE) -> 45000 | C17: =INDEX($L$2:$L$25,MATCH(A17,$K$2:$K$25,0)) -> 45000 | D17: =INDEX($L$2:$L$25,MATCH(A17,$K$2:$K$25,0)) -> 45000 | E17: =INDEX($L$2:$L$25,MATCH(K17,$K$2:$K$25,0)) -> 45000 | K17: Cupboard | L17: 45000 | R17: =INDEX($K$2:$L$25,MATCH(A17,$K$2:$K$25,0),2) -> 45000
A18: Speaker | B18: =VLOOKUP(A18,$K$2:$L$25,2,FALSE) -> 25000 | C18: =INDEX($L$2:$L$25,MATCH(A18,$K$2:$K$25,0)) -> 25000 | D18: =INDEX($L$2:$L$25,MATCH(A18,$K$2:$K$25,0)) -> 25000 | E18: =INDEX($L$2:$L$25,MATCH(K18,$K$2:$K$25,0)) -> 25000 | K18: Speaker | L18: 25000 | R18: =INDEX($K$2:$L$25,MATCH(A18,$K$2:$K$25,0),2) -> 25000
A19: Skirt | B19: =VLOOKUP(A19,$K$2:$L$25,2,FALSE) -> 1000 | C19: =INDEX($L$2:$L$25,MATCH(A19,$K$2:$K$25,0)) -> 1000 | D19: =INDEX($L$2:$L$25,MATCH(A19,$K$2:$K$25,0)) -> 1000 | E19: =INDEX($L$2:$L$25,MATCH(K19,$K$2:$K$25,0)) -> 1000 | K19: Skirt | L19: 1000 | R19: =INDEX($K$2:$L$25,MATCH(A19,$K$2:$K$25,0),2) -> 1000
A20: Stool | B20: =VLOOKUP(A20,$K$2:$L$25,2,FALSE) -> 1000 | C20: =INDEX($L$2:$L$25,MATCH(A20,$K$2:$K$25,0)) -> 1000 | D20: =INDEX($L$2:$L$25,MATCH(A20,$K$2:$K$25,0)) -> 1000 | E20: =INDEX($L$2:$L$25,MATCH(K20,$K$2:$K$25,0)) -> 1000 | K20: Stool | L20: 1000 | R20: =INDEX($K$2:$L$25,MATCH(A20,$K$2:$K$25,0),2) -> 1000
A21: Keyboard | B21: =VLOOKUP(A21,$K$2:$L$25,2,FALSE) -> 2000 | C21: =INDEX($L$2:$L$25,MATCH(A21,$K$2:$K$25,0)) -> 2000 | D21: =INDEX($L$2:$L$25,MATCH(A21,$K$2:$K$25,0)) -> 2000 | E21: =INDEX($L$2:$L$25,MATCH(K21,$K$2:$K$25,0)) -> 2000 | K21: Keyboard | L21: 2000 | R21: =INDEX($K$2:$L$25,MATCH(A21,$K$2:$K$25,0),2) -> 2000
A22: Watch | B22: =VLOOKUP(A22,$K$2:$L$25,2,FALSE) -> 1500 | C22: =INDEX($L$2:$L$25,MATCH(A22,$K$2:$K$25,0)) -> 1500 | D22: =INDEX($L$2:$L$25,MATCH(A22,$K$2:$K$25,0)) -> 1500 | E22: =INDEX($L$2:$L$25,MATCH(K22,$K$2:$K$25,0)) -> 1500 | K22: Watch | L22: 1500 | R22: =INDEX($K$2:$L$25,MATCH(A22,$K$2:$K$25,0),2) -> 1500
A23: Wardrobe | B23: =VLOOKUP(A23,$K$2:$L$25,2,FALSE) -> 45000 | C23: =INDEX($L$2:$L$25,MATCH(A23,$K$2:$K$25,0)) -> 45000 | D23: =INDEX($L$2:$L$25,MATCH(A23,$K$2:$K$25,0)) -> 45000 | E23: =INDEX($L$2:$L$25,MATCH(K23,$K$2:$K$25,0)) -> 45000 | K23: Wardrobe | L23: 45000 | R23: =INDEX($K$2:$L$25,MATCH(A23,$K$2:$K$25,0),2) -> 45000
A24: Printer | B24: =VLOOKUP(A24,$K$2:$L$25,2,FALSE) -> 4000 | C24: =INDEX($L$2:$L$25,MATCH(A24,$K$2:$K$25,0)) -> 4000 | D24: =INDEX($L$2:$L$25,MATCH(A24,$K$2:$K$25,0)) -> 4000 | E24: =INDEX($L$2:$L$25,MATCH(K24,$K$2:$K$25,0)) -> 4000 | K24: Printer | L24: 4000 | R24: =INDEX($K$2:$L$25,MATCH(A24,$K$2:$K$25,0),2) -> 4000
A25: T-Shirt | B25: =VLOOKUP(A25,$K$2:$L$25,2,FALSE) -> 50000 | C25: =INDEX($L$2:$L$25,MATCH(A25,$K$2:$K$25,0)) -> 50000 | D25: =INDEX($L$2:$L$25,MATCH(A25,$K$2:$K$25,0)) -> 50000 | E25: =INDEX($L$2:$L$25,MATCH(K25,$K$2:$K$25,0)) -> 50000 | K25: T-Shirt | L25: 50000 | R25: =INDEX($K$2:$L$25,MATCH(A25,$K$2:$K$25,0),2) -> 50000
A26: Desk | B26: =VLOOKUP(A26,$K$2:$L$25,2,FALSE) -> #N/A | C26: =INDEX($L$2:$L$25,MATCH(A26,$K$2:$K$25,0)) -> #N/A | D26: =INDEX($L$2:$L$25,MATCH(A26,$K$2:$K$25,0)) -> #N/A | E26: =INDEX($L$2:$L$25,MATCH(K26,$K$2:$K$25,0)) -> #N/A | K26: Desk | R26: =INDEX($K$2:$L$25,MATCH(A26,$K$2:$K$25,0),2) -> #N/A
A27: TV | B27: =VLOOKUP(A27,$K$2:$L$25,2,FALSE) -> #N/A | C27: =INDEX($L$2:$L$25,MATCH(A27,$K$2:$K$25,0)) -> #N/A | D27: =INDEX($L$2:$L$25,MATCH(A27,$K$2:$K$25,0)) -> #N/A | E27: =INDEX($L$2:$L$25,MATCH(K27,$K$2:$K$25,0)) -> #N/A | R27: =INDEX($K$2:$L$25,MATCH(A27,$K$2:$K$25,0),2) -> #N/A
A28: Belt | B28: =VLOOKUP(A28,$K$2:$L$25,2,FALSE) -> #N/A | C28: =INDEX($L$2:$L$25,MATCH(A28,$K$2:$K$25,0)) -> #N/A | D28: =INDEX($L$2:$L$25,MATCH(A28,$K$2:$K$25,0)) -> #N/A | E28: =INDEX($L$2:$L$25,MATCH(K28,$K$2:$K$25,0)) -> #N/A
A29: Recliner | B29: =VLOOKUP(A29,$K$2:$L$25,2,FALSE) -> #N/A | C29: =INDEX($L$2:$L$25,MATCH(A29,$K$2:$K$25,0)) -> #N/A | D29: =INDEX($L$2:$L$25,MATCH(A29,$K$2:$K$25,0)) -> #N/A | E29: =INDEX($L$2:$L$25,MATCH(K29,$K$2:$K$25,0)) -> #N/A
A30: Mouse | B30: =VLOOKUP(A30,$K$2:$L$25,2,FALSE) -> #N/A | C30: =INDEX($L$2:$L$25,MATCH(A30,$K$2:$K$25,0)) -> #N/A | D30: =INDEX($L$2:$L$25,MATCH(A30,$K$2:$K$25,0)) -> #N/A | E30: =INDEX($L$2:$L$25,MATCH(K30,$K$2:$K$25,0)) -> #N/A
A31: Cap | B31: =VLOOKUP(A31,$K$2:$L$25,2,FALSE) -> #N/A | C31: =INDEX($L$2:$L$25,MATCH(A31,$K$2:$K$25,0)) -> #N/A | D31: =INDEX($L$2:$L$25,MATCH(A31,$K$2:$K$25,0)) -> #N/A | E31: =INDEX($L$2:$L$25,MATCH(K31,$K$2:$K$25,0)) -> #N/A
A32: Shelf | B32: =VLOOKUP(A32,$K$2:$L$25,2,FALSE) -> #N/A | C32: =INDEX($L$2:$L$25,MATCH(A32,$K$2:$K$25,0)) -> #N/A | D32: =INDEX($L$2:$L$25,MATCH(A32,$K$2:$K$25,0)) -> #N/A | E32: =INDEX($L$2:$L$25,MATCH(K32,$K$2:$K$25,0)) -> #N/A
A33: Router | B33: =VLOOKUP(A33,$K$2:$L$25,2,FALSE) -> #N/A | C33: =INDEX($L$2:$L$25,MATCH(A33,$K$2:$K$25,0)) -> #N/A | D33: =INDEX($L$2:$L$25,MATCH(A33,$K$2:$K$25,0)) -> #N/A | E33: =INDEX($L$2:$L$25,MATCH(K33,$K$2:$K$25,0)) -> #N/A
A34: Kurta | B34: =VLOOKUP(A34,$K$2:$L$25,2,FALSE) -> #N/A | C34: =INDEX($L$2:$L$25,MATCH(A34,$K$2:$K$25,0)) -> #N/A | D34: =INDEX($L$2:$L$25,MATCH(A34,$K$2:$K$25,0)) -> #N/A | E34: =INDEX($L$2:$L$25,MATCH(K34,$K$2:$K$25,0)) -> #N/A
A35: Dining Set | B35: =VLOOKUP(A35,$K$2:$L$25,2,FALSE) -> #N/A | C35: =INDEX($L$2:$L$25,MATCH(A35,$K$2:$K$25,0)) -> #N/A | D35: =INDEX($L$2:$L$25,MATCH(A35,$K$2:$K$25,0)) -> #N/A | E35: =INDEX($L$2:$L$25,MATCH(K35,$K$2:$K$25,0)) -> #N/A
A36: Console | B36: =VLOOKUP(A36,$K$2:$L$25,2,FALSE) -> #N/A | C36: =INDEX($L$2:$L$25,MATCH(A36,$K$2:$K$25,0)) -> #N/A | D36: =INDEX($L$2:$L$25,MATCH(A36,$K$2:$K$25,0)) -> #N/A | E36: =INDEX($L$2:$L$25,MATCH(K36,$K$2:$K$25,0)) -> #N/A
A37: Saree | B37: =VLOOKUP(A37,$K$2:$L$25,2,FALSE) -> #N/A | C37: =INDEX($L$2:$L$25,MATCH(A37,$K$2:$K$25,0)) -> #N/A | D37: =INDEX($L$2:$L$25,MATCH(A37,$K$2:$K$25,0)) -> #N/A | E37: =INDEX($L$2:$L$25,MATCH(K37,$K$2:$K$25,0)) -> #N/A
A38: Lamp | B38: =VLOOKUP(A38,$K$2:$L$25,2,FALSE) -> #N/A | C38: =INDEX($L$2:$L$25,MATCH(A38,$K$2:$K$25,0)) -> #N/A | D38: =INDEX($L$2:$L$25,MATCH(A38,$K$2:$K$25,0)) -> #N/A | E38: =INDEX($L$2:$L$25,MATCH(K38,$K$2:$K$25,0)) -> #N/A
A39: Drone | B39: =VLOOKUP(A39,$K$2:$L$25,2,FALSE) -> #N/A | C39: =INDEX($L$2:$L$25,MATCH(A39,$K$2:$K$25,0)) -> #N/A | D39: =INDEX($L$2:$L$25,MATCH(A39,$K$2:$K$25,0)) -> #N/A | E39: =INDEX($L$2:$L$25,MATCH(K39,$K$2:$K$25,0)) -> #N/A
... A45: Camera Lens | B45: =VLOOKUP(A45,$K$2:$L$25,2,FALSE) -> #N/A | C45: =INDEX($L$2:$L$25,MATCH(A45,$K$2:$K$25,0)) -> #N/A | D45: =INDEX($L$2:$L$25,MATCH(A45,$K$2:$K$25,0)) -> #N/A | E45: =INDEX($L$2:$L$25,MATCH(K45,$K$2:$K$25,0)) -> #N/A
...
